Workbook
Name Elem: #REF!
Name Elem2: #REF!
Name PrivateSchool: #REF!

Sheet Elem_Needs_Updated
A1: UPDATED TEACHERS' NEEDS FOR SY 2025-2026
A5: as of May 2026
B6: Class Size | M6: 50-60 | N6: 30-35 | O6: 30-35 | P6: 30-35 | Q6: 40-45 | R6: 40-45 | S6: 40-45 | T6: 15 | U6: 55 | V6: 33 | W6: 33 | X6: 33 | Y6: 43 | Z6: 43 | AA6: 43 | AB6: 15
A7: School | B7: Elementary School | C7: District | D7: Enrolment (SY 2025-2026)-as of May 21, 2026 | M7: Class Size | U7: Number of Sections/Classes | AD7: Teachers as of May 2026
D8: K | E8: G1 | F8: G2 | G8: G3 | H8: G4 | I8: G5 | J8: G6 | K8: NG | L8: TOTAL | M8: K | N8: G1 | O8: G2 | P8: G3 | Q8: G4 | R8: G5 | S8: G6 | T8: TOTAL | U8: K | V8: G1 | W8: G2 | X8: G3 | Y8: G4 | Z8: G5 | AA8: G6 | AB8: NG | AC8: TOTAL | AD8: Required | AE8: Existing | AF8: GAP
A9: 119964 | B9: Buaya ES | C9: 1 | D9: =_xlfn.XLOOKUP($A9,Enrolment!$A:$A,Enrolment!C:C,,,) -> 247 | E9: =_xlfn.XLOOKUP($A9,Enrolment!$A:$A,Enrolment!D:D,,,) -> 235 | F9: =_xlfn.XLOOKUP($A9,Enrolment!$A:$A,Enrolment!E:E,,,) -> 233 | G9: =_xlfn.XLOOKUP($A9,Enrolment!$A:$A,Enrolment!F:F,,,) -> 243 | H9: =_xlfn.XLOOKUP($A9,Enrolment!$A:$A,Enrolment!G:G,,,) -> 229 | I9: =_xlfn.XLOOKUP($A9,Enrolment!$A:$A,Enrolment!H:H,,,) -> 293 | J9: =_xlfn.XLOOKUP($A9,Enrolment!$A:$A,Enrolment!I:I,,,) -> 234 | K9: =_xlfn.XLOOKUP(A9,Enrolment!$A:$A,Enrolment!J:J,,,) -> 0 | L9: =SUM(D9:K9) -> 1714 | M9: =ROUND(D9/U9,0) -> 49 | N9: =ROUND(E9/V9,0) -> 29 | O9: =ROUND(F9/W9,0) -> 29 | P9: =ROUND(G9/X9,0) -> 30 | Q9: =ROUND(H9/Y9,0) -> 38 | R9: =ROUND(I9/Z9,0) -> 42 | S9: =ROUND(J9/AA9,0) -> 39 | T9: =SUM(M9:S9) -> 256 | U9: =ROUNDUP(D9/55,0) -> 5 | V9: =ROUNDUP(E9/33,0) -> 8 | W9: =ROUNDUP(F9/33,0) -> 8 | X9: =ROUNDUP(G9/33,0) -> 8 | Y9: =ROUNDUP(H9/43,0) -> 6 | Z9: =ROUNDUP(I9/43,0) -> 7 | AA9: =ROUNDUP(J9/43,0) -> 6 | AB9: =ROUNDUP(K9/15,0) -> 0 | AC9: =SUM(U9:AB9) -> 48 | AD9: =AB9+SUM(U9:W9)+SUM(X9:AA9)*1.25 -> 54.75 | AE9: =_xlfn.XLOOKUP(A9,Teachers!A:A,Teachers!C:C,,,) -> 51 | AF9: =ROUND(AD9-AE9,0) -> 4
A10: 119986 | B10: Babag II ES | C10: 8 | D10: =_xlfn.XLOOKUP($A10,Enrolment!$A:$A,Enrolment!C:C,,,) -> 197 | E10: =_xlfn.XLOOKUP($A10,Enrolment!$A:$A,Enrolment!D:D,,,) -> 188 | F10: =_xlfn.XLOOKUP($A10,Enrolment!$A:$A,Enrolment!E:E,,,) -> 204 | G10: =_xlfn.XLOOKUP($A10,Enrolment!$A:$A,Enrolment!F:F,,,) -> 235 | H10: =_xlfn.XLOOKUP($A10,Enrolment!$A:$A,Enrolment!G:G,,,) -> 227 | I10: =_xlfn.XLOOKUP($A10,Enrolment!$A:$A,Enrolment!H:H,,,) -> 284 | J10: =_xlfn.XLOOKUP($A10,Enrolment!$A:$A,Enrolment!I:I,,,) -> 220 | K10: =_xlfn.XLOOKUP(A10,Enrolment!$A:$A,Enrolment!J:J,,,) -> 0 | L10: =SUM(D10:K10) -> 1555 | M10: =ROUND(D10/U10,0) -> 49 | N10: =ROUND(E10/V10,0) -> 31 | O10: =ROUND(F10/W10,0) -> 29 | P10: =ROUND(G10/X10,0) -> 29 | Q10: =ROUND(H10/Y10,0) -> 38 | R10: =ROUND(I10/Z10,0) -> 41 | S10: =ROUND(J10/AA10,0) -> 37 | T10: =SUM(M10:S10) -> 254 | U10: =ROUNDUP(D10/55,0) -> 4 | V10: =ROUNDUP(E10/33,0) -> 6 | W10: =ROUNDUP(F10/33,0) -> 7 | X10: =ROUNDUP(G10/33,0) -> 8 | Y10: =ROUNDUP(H10/43,0) -> 6 | Z10: =ROUNDUP(I10/43,0) -> 7 | AA10: =ROUNDUP(J10/43,0) -> 6 | AB10: =ROUNDUP(K10/15,0) -> 0 | AC10: =SUM(U10:AB10) -> 44 | AD10: =AB10+SUM(U10:W10)+SUM(X10:AA10)*1.25 -> 50.75 | AE10: =_xlfn.XLOOKUP(A10,Teachers!A:A,Teachers!C:C,,,) -> 43 | AF10: =ROUND(AD10-AE10,0) -> 8
A11: 119974 | B11: Bagong Silang ES | C11: 4 | D11: =_xlfn.XLOOKUP($A11,Enrolment!$A:$A,Enrolment!C:C,,,) -> 217 | E11: =_xlfn.XLOOKUP($A11,Enrolment!$A:$A,Enrolment!D:D,,,) -> 207 | F11: =_xlfn.XLOOKUP($A11,Enrolment!$A:$A,Enrolment!E:E,,,) -> 209 | G11: =_xlfn.XLOOKUP($A11,Enrolment!$A:$A,Enrolment!F:F,,,) -> 221 | H11: =_xlfn.XLOOKUP($A11,Enrolment!$A:$A,Enrolment!G:G,,,) -> 225 | I11: =_xlfn.XLOOKUP($A11,Enrolment!$A:$A,Enrolment!H:H,,,) -> 244 | J11: =_xlfn.XLOOKUP($A11,Enrolment!$A:$A,Enrolment!I:I,,,) -> 201 | K11: =_xlfn.XLOOKUP(A11,Enrolment!$A:$A,Enrolment!J:J,,,) -> 0 | L11: =SUM(D11:K11) -> 1524 | M11: =ROUND(D11/U11,0) -> 54 | N11: =ROUND(E11/V11,0) -> 30 | O11: =ROUND(F11/W11,0) -> 30 | P11: =ROUND(G11/X11,0) -> 32 | Q11: =ROUND(H11/Y11,0) -> 38 | R11: =ROUND(I11/Z11,0) -> 41 | S11: =ROUND(J11/AA11,0) -> 40 | T11: =SUM(M11:S11) -> 265 | U11: =ROUNDUP(D11/55,0) -> 4 | V11: =ROUNDUP(E11/33,0) -> 7 | W11: =ROUNDUP(F11/33,0) -> 7 | X11: =ROUNDUP(G11/33,0) -> 7 | Y11: =ROUNDUP(H11/43,0) -> 6 | Z11: =ROUNDUP(I11/43,0) -> 6 | AA11: =ROUNDUP(J11/43,0) -> 5 | AB11: =ROUNDUP(K11/15,0) -> 0 | AC11: =SUM(U11:AB11) -> 42 | AD11: =AB11+SUM(U11:W11)+SUM(X11:AA11)*1.25 -> 48 | AE11: =_xlfn.XLOOKUP(A11,Teachers!A:A,Teachers!C:C,,,) -> 49 | AF11: =ROUND(AD11-AE11,0) -> -1
A12: 119975 | B12: Basak ES | C12: 6 | D12: =_xlfn.XLOOKUP($A12,Enrolment!$A:$A,Enrolment!C:C,,,) -> 309 | E12: =_xlfn.XLOOKUP($A12,Enrolment!$A:$A,Enrolment!D:D,,,) -> 294 | F12: =_xlfn.XLOOKUP($A12,Enrolment!$A:$A,Enrolment!E:E,,,) -> 244 | G12: =_xlfn.XLOOKUP($A12,Enrolment!$A:$A,Enrolment!F:F,,,) -> 309 | H12: =_xlfn.XLOOKUP($A12,Enrolment!$A:$A,Enrolment!G:G,,,) -> 281 | I12: =_xlfn.XLOOKUP($A12,Enrolment!$A:$A,Enrolment!H:H,,,) -> 345 | J12: =_xlfn.XLOOKUP($A12,Enrolment!$A:$A,Enrolment!I:I,,,) -> 282 | K12: =_xlfn.XLOOKUP(A12,Enrolment!$A:$A,Enrolment!J:J,,,) -> 0 | L12: =SUM(D12:K12) -> 2064 | M12: =ROUND(D12/U12,0) -> 52 | N12: =ROUND(E12/V12,0) -> 33 | O12: =ROUND(F12/W12,0) -> 31 | P12: =ROUND(G12/X12,0) -> 31 | Q12: =ROUND(H12/Y12,0) -> 40 | R12: =ROUND(I12/Z12,0) -> 38 | S12: =ROUND(J12/AA12,0) -> 40 | T12: =SUM(M12:S12) -> 265 | U12: =ROUNDUP(D12/55,0) -> 6 | V12: =ROUNDUP(E12/33,0) -> 9 | W12: =ROUNDUP(F12/33,0) -> 8 | X12: =ROUNDUP(G12/33,0) -> 10 | Y12: =ROUNDUP(H12/43,0) -> 7 | Z12: =ROUNDUP(I12/43,0) -> 9 | AA12: =ROUNDUP(J12/43,0) -> 7 | AB12: =ROUNDUP(K12/15,0) -> 0 | AC12: =SUM(U12:AB12) -> 56 | AD12: =AB12+SUM(U12:W12)+SUM(X12:AA12)*1.25 -> 64.25 | AE12: =_xlfn.XLOOKUP(A12,Teachers!A:A,Teachers!C:C,,,) -> 59 | AF12: =ROUND(AD12-AE12,0) -> 5
A13: 119978 | B13: Maribago ES | C13: 4 | D13: =_xlfn.XLOOKUP($A13,Enrolment!$A:$A,Enrolment!C:C,,,) -> 235 | E13: =_xlfn.XLOOKUP($A13,Enrolment!$A:$A,Enrolment!D:D,,,) -> 224 | F13: =_xlfn.XLOOKUP($A13,Enrolment!$A:$A,Enrolment!E:E,,,) -> 229 | G13: =_xlfn.XLOOKUP($A13,Enrolment!$A:$A,Enrolment!F:F,,,) -> 237 | H13: =_xlfn.XLOOKUP($A13,Enrolment!$A:$A,Enrolment!G:G,,,) -> 235 | I13: =_xlfn.XLOOKUP($A13,Enrolment!$A:$A,Enrolment!H:H,,,) -> 289 | J13: =_xlfn.XLOOKUP($A13,Enrolment!$A:$A,Enrolment!I:I,,,) -> 274 | K13: =_xlfn.XLOOKUP(A13,Enrolment!$A:$A,Enrolment!J:J,,,) -> 0 | L13: =SUM(D13:K13) -> 1723 | M13: =ROUND(D13/U13,0) -> 47 | N13: =ROUND(E13/V13,0) -> 32 | O13: =ROUND(F13/W13,0) -> 33 | P13: =ROUND(G13/X13,0) -> 30 | Q13: =ROUND(H13/Y13,0) -> 39 | R13: =ROUND(I13/Z13,0) -> 41 | S13: =ROUND(J13/AA13,0) -> 39 | T13: =SUM(M13:S13) -> 261 | U13: =ROUNDUP(D13/55,0) -> 5 | V13: =ROUNDUP(E13/33,0) -> 7 | W13: =ROUNDUP(F13/33,0) -> 7 | X13: =ROUNDUP(G13/33,0) -> 8 | Y13: =ROUNDUP(H13/43,0) -> 6 | Z13: =ROUNDUP(I13/43,0) -> 7 | AA13: =ROUNDUP(J13/43,0) -> 7 | AB13: =ROUNDUP(K13/15,0) -> 0 | AC13: =SUM(U13:AB13) -> 47 | AD13: =AB13+SUM(U13:W13)+SUM(X13:AA13)*1.25 -> 54 | AE13: =_xlfn.XLOOKUP(A13,Teachers!A:A,Teachers!C:C,,,) -> 50 | AF13: =ROUND(AD13-AE13,0) -> 4
A14: 119985 | B14: Babag I ES | C14: 8 | D14: =_xlfn.XLOOKUP($A14,Enrolment!$A:$A,Enrolment!C:C,,,) -> 261 | E14: =_xlfn.XLOOKUP($A14,Enrolment!$A:$A,Enrolment!D:D,,,) -> 249 | F14: =_xlfn.XLOOKUP($A14,Enrolment!$A:$A,Enrolment!E:E,,,) -> 265 | G14: =_xlfn.XLOOKUP($A14,Enrolment!$A:$A,Enrolment!F:F,,,) -> 294 | H14: =_xlfn.XLOOKUP($A14,Enrolment!$A:$A,Enrolment!G:G,,,) -> 337 | I14: =_xlfn.XLOOKUP($A14,Enrolment!$A:$A,Enrolment!H:H,,,) -> 309 | J14: =_xlfn.XLOOKUP($A14,Enrolment!$A:$A,Enrolment!I:I,,,) -> 305 | K14: =_xlfn.XLOOKUP(A14,Enrolment!$A:$A,Enrolment!J:J,,,) -> 0 | L14: =SUM(D14:K14) -> 2020 | M14: =ROUND(D14/U14,0) -> 52 | N14: =ROUND(E14/V14,0) -> 31 | O14: =ROUND(F14/W14,0) -> 29 | P14: =ROUND(G14/X14,0) -> 33 | Q14: =ROUND(H14/Y14,0) -> 42 | R14: =ROUND(I14/Z14,0) -> 39 | S14: =ROUND(J14/AA14,0) -> 38 | T14: =SUM(M14:S14) -> 264 | U14: =ROUNDUP(D14/55,0) -> 5 | V14: =ROUNDUP(E14/33,0) -> 8 | W14: =ROUNDUP(F14/33,0) -> 9 | X14: =ROUNDUP(G14/33,0) -> 9 | Y14: =ROUNDUP(H14/43,0) -> 8 | Z14: =ROUNDUP(I14/43,0) -> 8 | AA14: =ROUNDUP(J14/43,0) -> 8 | AB14: =ROUNDUP(K14/15,0) -> 0 | AC14: =SUM(U14:AB14) -> 55 | AD14: =AB14+SUM(U14:W14)+SUM(X14:AA14)*1.25 -> 63.25 | AE14: =_xlfn.XLOOKUP(A14,Teachers!A:A,Teachers!C:C,,,) -> 69 | AF14: =ROUND(AD14-AE14,0) -> -6
A15: 119984 | B15: Sudtonggan ES | C15: 6 | D15: =_xlfn.XLOOKUP($A15,Enrolment!$A:$A,Enrolment!C:C,,,) -> 237 | E15: =_xlfn.XLOOKUP($A15,Enrolment!$A:$A,Enrolment!D:D,,,) -> 226 | F15: =_xlfn.XLOOKUP($A15,Enrolment!$A:$A,Enrolment!E:E,,,) -> 192 | G15: =_xlfn.XLOOKUP($A15,Enrolment!$A:$A,Enrolment!F:F,,,) -> 215 | H15: =_xlfn.XLOOKUP($A15,Enrolment!$A:$A,Enrolment!G:G,,,) -> 270 | I15: =_xlfn.XLOOKUP($A15,Enrolment!$A:$A,Enrolment!H:H,,,) -> 255 | J15: =_xlfn.XLOOKUP($A15,Enrolment!$A:$A,Enrolment!I:I,,,) -> 223 | K15: =_xlfn.XLOOKUP(A15,Enrolment!$A:$A,Enrolment!J:J,,,) -> 0 | L15: =SUM(D15:K15) -> 1618 | M15: =ROUND(D15/U15,0) -> 47 | N15: =ROUND(E15/V15,0) -> 32 | O15: =ROUND(F15/W15,0) -> 32 | P15: =ROUND(G15/X15,0) -> 31 | Q15: =ROUND(H15/Y15,0) -> 39 | R15: =ROUND(I15/Z15,0) -> 43 | S15: =ROUND(J15/AA15,0) -> 37 | T15: =SUM(M15:S15) -> 261 | U15: =ROUNDUP(D15/55,0) -> 5 | V15: =ROUNDUP(E15/33,0) -> 7 | W15: =ROUNDUP(F15/33,0) -> 6 | X15: =ROUNDUP(G15/33,0) -> 7 | Y15: =ROUNDUP(H15/43,0) -> 7 | Z15: =ROUNDUP(I15/43,0) -> 6 | AA15: =ROUNDUP(J15/43,0) -> 6 | AB15: =ROUNDUP(K15/15,0) -> 0 | AC15: =SUM(U15:AB15) -> 44 | AD15: =AB15+SUM(U15:W15)+SUM(X15:AA15)*1.25 -> 50.5 | AE15: =_xlfn.XLOOKUP(A15,Teachers!A:A,Teachers!C:C,,,) -> 49 | AF15: =ROUND(AD15-AE15,0) -> 2
A16: 119968 | B16: Pajo ES | C16: 3 | D16: =_xlfn.XLOOKUP($A16,Enrolment!$A:$A,Enrolment!C:C,,,) -> 278 | E16: =_xlfn.XLOOKUP($A16,Enrolment!$A:$A,Enrolment!D:D,,,) -> 265 | F16: =_xlfn.XLOOKUP($A16,Enrolment!$A:$A,Enrolment!E:E,,,) -> 237 | G16: =_xlfn.XLOOKUP($A16,Enrolment!$A:$A,Enrolment!F:F,,,) -> 247 | H16: =_xlfn.XLOOKUP($A16,Enrolment!$A:$A,Enrolment!G:G,,,) -> 285 | I16: =_xlfn.XLOOKUP($A16,Enrolment!$A:$A,Enrolment!H:H,,,) -> 281 | J16: =_xlfn.XLOOKUP($A16,Enrolment!$A:$A,Enrolment!I:I,,,) -> 254 | K16: =_xlfn.XLOOKUP(A16,Enrolment!$A:$A,Enrolment!J:J,,,) -> 0 | L16: =SUM(D16:K16) -> 1847 | M16: =ROUND(D16/U16,0) -> 46 | N16: =ROUND(E16/V16,0) -> 29 | O16: =ROUND(F16/W16,0) -> 30 | P16: =ROUND(G16/X16,0) -> 31 | Q16: =ROUND(H16/Y16,0) -> 41 | R16: =ROUND(I16/Z16,0) -> 40 | S16: =ROUND(J16/AA16,0) -> 42 | T16: =SUM(M16:S16) -> 259 | U16: =ROUNDUP(D16/55,0) -> 6 | V16: =ROUNDUP(E16/33,0) -> 9 | W16: =ROUNDUP(F16/33,0) -> 8 | X16: =ROUNDUP(G16/33,0) -> 8 | Y16: =ROUNDUP(H16/43,0) -> 7 | Z16: =ROUNDUP(I16/43,0) -> 7 | AA16: =ROUNDUP(J16/43,0) -> 6 | AB16: =ROUNDUP(K16/15,0) -> 0 | AC16: =SUM(U16:AB16) -> 51 | AD16: =AB16+SUM(U16:W16)+SUM(X16:AA16)*1.25 -> 58 | AE16: =_xlfn.XLOOKUP(A16,Teachers!A:A,Teachers!C:C,,,) -> 49 | AF16: =ROUND(AD16-AE16,0) -> 9
A17: 119972 | B17: Abuno ES | C17: 4 | D17: =_xlfn.XLOOKUP($A17,Enrolment!$A:$A,Enrolment!C:C,,,) -> 168 | E17: =_xlfn.XLOOKUP($A17,Enrolment!$A:$A,Enrolment!D:D,,,) -> 160 | F17: =_xlfn.XLOOKUP($A17,Enrolment!$A:$A,Enrolment!E:E,,,) -> 167 | G17: =_xlfn.XLOOKUP($A17,Enrolment!$A:$A,Enrolment!F:F,,,) -> 195 | H17: =_xlfn.XLOOKUP($A17,Enrolment!$A:$A,Enrolment!G:G,,,) -> 200 | I17: =_xlfn.XLOOKUP($A17,Enrolment!$A:$A,Enrolment!H:H,,,) -> 196 | J17: =_xlfn.XLOOKUP($A17,Enrolment!$A:$A,Enrolment!I:I,,,) -> 184 | K17: =_xlfn.XLOOKUP(A17,Enrolment!$A:$A,Enrolment!J:J,,,) -> 0 | L17: =SUM(D17:K17) -> 1270 | M17: =ROUND(D17/U17,0) -> 42 | N17: =ROUND(E17/V17,0) -> 32 | O17: =ROUND(F17/W17,0) -> 28 | P17: =ROUND(G17/X17,0) -> 33 | Q17: =ROUND(H17/Y17,0) -> 40 | R17: =ROUND(I17/Z17,0) -> 39 | S17: =ROUND(J17/AA17,0) -> 37 | T17: =SUM(M17:S17) -> 251 | U17: =ROUNDUP(D17/55,0) -> 4 | V17: =ROUNDUP(E17/33,0) -> 5 | W17: =ROUNDUP(F17/33,0) -> 6 | X17: =ROUNDUP(G17/33,0) -> 6 | Y17: =ROUNDUP(H17/43,0) -> 5 | Z17: =ROUNDUP(I17/43,0) -> 5 | AA17: =ROUNDUP(J17/43,0) -> 5 | AB17: =ROUNDUP(K17/15,0) -> 0 | AC17: =SUM(U17:AB17) -> 36 | AD17: =AB17+SUM(U17:W17)+SUM(X17:AA17)*1.25 -> 41.25 | AE17: =_xlfn.XLOOKUP(A17,Teachers!A:A,Teachers!C:C,,,) -> 40 | AF17: =ROUND(AD17-AE17,0) -> 1
A18: 119960 | B18: Talima ES | C18: 10 | D18: =_xlfn.XLOOKUP($A18,Enrolment!$A:$A,Enrolment!C:C,,,) -> 149 | E18: =_xlfn.XLOOKUP($A18,Enrolment!$A:$A,Enrolment!D:D,,,) -> 142 | F18: =_xlfn.XLOOKUP($A18,Enrolment!$A:$A,Enrolment!E:E,,,) -> 126 | G18: =_xlfn.XLOOKUP($A18,Enrolment!$A:$A,Enrolment!F:F,,,) -> 126 | H18: =_xlfn.XLOOKUP($A18,Enrolment!$A:$A,Enrolment!G:G,,,) -> 105 | I18: =_xlfn.XLOOKUP($A18,Enrolment!$A:$A,Enrolment!H:H,,,) -> 117 | J18: =_xlfn.XLOOKUP($A18,Enrolment!$A:$A,Enrolment!I:I,,,) -> 136 | K18: =_xlfn.XLOOKUP(A18,Enrolment!$A:$A,Enrolment!J:J,,,) -> 0 | L18: =SUM(D18:K18) -> 901 | M18: =ROUND(D18/U18,0) -> 50 | N18: =ROUND(E18/V18,0) -> 28 | O18: =ROUND(F18/W18,0) -> 32 | P18: =ROUND(G18/X18,0) -> 32 | Q18: =ROUND(H18/Y18,0) -> 35 | R18: =ROUND(I18/Z18,0) -> 39 | S18: =ROUND(J18/AA18,0) -> 34 | T18: =SUM(M18:S18) -> 250 | U18: =ROUNDUP(D18/55,0) -> 3 | V18: =ROUNDUP(E18/33,0) -> 5 | W18: =ROUNDUP(F18/33,0) -> 4 | X18: =ROUNDUP(G18/33,0) -> 4 | Y18: =ROUNDUP(H18/43,0) -> 3 | Z18: =ROUNDUP(I18/43,0) -> 3 | AA18: =ROUNDUP(J18/43,0) -> 4 | AB18: =ROUNDUP(K18/15,0) -> 0 | AC18: =SUM(U18:AB18) -> 26 | AD18: =AB18+SUM(U18:W18)+SUM(X18:AA18)*1.25 -> 29.5 | AE18: =_xlfn.XLOOKUP(A18,Teachers!A:A,Teachers!C:C,,,) -> 28 | AF18: =ROUND(AD18-AE18,0) -> 2
A19: 119970 | B19: Pusok ES | C19: 3 | D19: =_xlfn.XLOOKUP($A19,Enrolment!$A:$A,Enrolment!C:C,,,) -> 342 | E19: =_xlfn.XLOOKUP($A19,Enrolment!$A:$A,Enrolment!D:D,,,) -> 326 | F19: =_xlfn.XLOOKUP($A19,Enrolment!$A:$A,Enrolment!E:E,,,) -> 285 | G19: =_xlfn.XLOOKUP($A19,Enrolment!$A:$A,Enrolment!F:F,,,) -> 342 | H19: =_xlfn.XLOOKUP($A19,Enrolment!$A:$A,Enrolment!G:G,,,) -> 343 | I19: =_xlfn.XLOOKUP($A19,Enrolment!$A:$A,Enrolment!H:H,,,) -> 423 | J19: =_xlfn.XLOOKUP($A19,Enrolment!$A:$A,Enrolment!I:I,,,) -> 369 | K19: =_xlfn.XLOOKUP(A19,Enrolment!$A:$A,Enrolment!J:J,,,) -> 0 | L19: =SUM(D19:K19) -> 2430 | M19: =ROUND(D19/U19,0) -> 49 | N19: =ROUND(E19/V19,0) -> 33 | O19: =ROUND(F19/W19,0) -> 32 | P19: =ROUND(G19/X19,0) -> 31 | Q19: =ROUND(H19/Y19,0) -> 43 | R19: =ROUND(I19/Z19,0) -> 42 | S19: =ROUND(J19/AA19,0) -> 41 | T19: =SUM(M19:S19) -> 271 | U19: =ROUNDUP(D19/55,0) -> 7 | V19: =ROUNDUP(E19/33,0) -> 10 | W19: =ROUNDUP(F19/33,0) -> 9 | X19: =ROUNDUP(G19/33,0) -> 11 | Y19: =ROUNDUP(H19/43,0) -> 8 | Z19: =ROUNDUP(I19/43,0) -> 10 | AA19: =ROUNDUP(J19/43,0) -> 9 | AB19: =ROUNDUP(K19/15,0) -> 0 | AC19: =SUM(U19:AB19) -> 64 | AD19: =AB19+SUM(U19:W19)+SUM(X19:AA19)*1.25 -> 73.5 | AE19: =_xlfn.XLOOKUP(A19,Teachers!A:A,Teachers!C:C,,,) -> 73 | AF19: =ROUND(AD19-AE19,0) -> 1
A20: 119963 | B20: Bankal ES | C20: 2 | D20: =_xlfn.XLOOKUP($A20,Enrolment!$A:$A,Enrolment!C:C,,,) -> 507 | E20: =_xlfn.XLOOKUP($A20,Enrolment!$A:$A,Enrolment!D:D,,,) -> 483 | F20: =_xlfn.XLOOKUP($A20,Enrolment!$A:$A,Enrolment!E:E,,,) -> 450 | G20: =_xlfn.XLOOKUP($A20,Enrolment!$A:$A,Enrolment!F:F,,,) -> 498 | H20: =_xlfn.XLOOKUP($A20,Enrolment!$A:$A,Enrolment!G:G,,,) -> 526 | I20: =_xlfn.XLOOKUP($A20,Enrolment!$A:$A,Enrolment!H:H,,,) -> 607 | J20: =_xlfn.XLOOKUP($A20,Enrolment!$A:$A,Enrolment!I:I,,,) -> 566 | K20: =_xlfn.XLOOKUP(A20,Enrolment!$A:$A,Enrolment!J:J,,,) -> 0 | L20: =SUM(D20:K20) -> 3637 | M20: =ROUND(D20/U20,0) -> 51 | N20: =ROUND(E20/V20,0) -> 32 | O20: =ROUND(F20/W20,0) -> 32 | P20: =ROUND(G20/X20,0) -> 31 | Q20: =ROUND(H20/Y20,0) -> 40 | R20: =ROUND(I20/Z20,0) -> 40 | S20: =ROUND(J20/AA20,0) -> 40 | T20: =SUM(M20:S20) -> 266 | U20: =ROUNDUP(D20/55,0) -> 10 | V20: =ROUNDUP(E20/33,0) -> 15 | W20: =ROUNDUP(F20/33,0) -> 14 | X20: =ROUNDUP(G20/33,0) -> 16 | Y20: =ROUNDUP(H20/43,0) -> 13 | Z20: =ROUNDUP(I20/43,0) -> 15 | AA20: =ROUNDUP(J20/43,0) -> 14 | AB20: =ROUNDUP(K20/15,0) -> 0 | AC20: =SUM(U20:AB20) -> 97 | AD20: =AB20+SUM(U20:W20)+SUM(X20:AA20)*1.25 -> 111.5 | AE20: =_xlfn.XLOOKUP(A20,Teachers!A:A,Teachers!C:C,,,) -> 105 | AF20: =ROUND(AD20-AE20,0) -> 7
... A52: 119989 | B52: Lapu-Lapu City CES | C52: 7 | D52: =_xlfn.XLOOKUP($A52,Enrolment!$A:$A,Enrolment!C:C,,,) -> 287 | E52: =_xlfn.XLOOKUP($A52,Enrolment!$A:$A,Enrolment!D:D,,,) -> 273 | F52: =_xlfn.XLOOKUP($A52,Enrolment!$A:$A,Enrolment!E:E,,,) -> 301 | G52: =_xlfn.XLOOKUP($A52,Enrolment!$A:$A,Enrolment!F:F,,,) -> 342 | H52: =_xlfn.XLOOKUP($A52,Enrolment!$A:$A,Enrolment!G:G,,,) -> 319 | I52: =_xlfn.XLOOKUP($A52,Enrolment!$A:$A,Enrolment!H:H,,,) -> 350 | J52: =_xlfn.XLOOKUP($A52,Enrolment!$A:$A,Enrolment!I:I,,,) -> 345 | K52: =_xlfn.XLOOKUP(A52,Enrolment!$A:$A,Enrolment!J:J,,,) -> 168 | L52: =SUM(D52:K52) -> 2385 | M52: =ROUND(D52/U52,0) -> 48 | N52: =ROUND(E52/V52,0) -> 30 | O52: =ROUND(F52/W52,0) -> 30 | P52: =ROUND(G52/X52,0) -> 31 | Q52: =ROUND(H52/Y52,0) -> 40 | R52: =ROUND(I52/Z52,0) -> 39 | S52: =ROUND(J52/AA52,0) -> 38 | T52: =SUM(M52:S52) -> 256 | U52: =ROUNDUP(D52/55,0) -> 6 | V52: =ROUNDUP(E52/33,0) -> 9 | W52: =ROUNDUP(F52/33,0) -> 10 | X52: =ROUNDUP(G52/33,0) -> 11 | Y52: =ROUNDUP(H52/43,0) -> 8 | Z52: =ROUNDUP(I52/43,0) -> 9 | AA52: =ROUNDUP(J52/43,0) -> 9 | AB52: =ROUNDUP(K52/15,0) -> 12 | AC52: =SUM(U52:AB52) -> 74 | AD52: =AB52+SUM(U52:W52)+SUM(X52:AA52)*1.25 -> 83.25 | AE52: =_xlfn.XLOOKUP(A52,Teachers!A:A,Teachers!C:C,,,) -> 81 | AF52: =ROUND(AD52-AE52,0) -> 2

Sheet Teachers
A1: SY 25-26 | B1: Name of School
A2: SCHOOLID | B2: Name of School | C2: No. of Teachers
A3: 119972 | B3: Abuno ES | C3: 40
A4: 119973 | B4: Agus ES | C4: 42
A5: 119985 | B5: Babag I ES | C5: 69
A6: 119986 | B6: Babag II ES | C6: 43
A7: 119974 | B7: Bagong Silang ES | C7: 49
A8: 119963 | B8: Bankal ES | C8: 105
A9: 119950 | B9: Baring ES | C9: 21
A10: 119975 | B10: Basak ES | C10: 59
A11: 119964 | B11: Buaya ES | C11: 51
A12: 119976 | B12: Buyong ES | C12: 39
A13: 119951 | B13: Candagsao ES | C13: 13
A14: 119987 | B14: Canjulao ES | C14: 43
... A46: 119962 | B46: Tungasan ES | C46: 14
B47: Grand Total | C47: 1842
A49: Note: Data on number of teachers was based from the HRIS Data c/o Sir Joel Ongco

Sheet Enrolment
B1: School | C1: Kinder | D1: Grade 1 | E1: Grade 2 | F1: Grade 3 | G1: Grade 4 | H1: Grade 5 | I1: Grade 6 | J1: Non-Graded | K1: Grand Total
A2: 119972 | B2: Abuno Elementary School | C2: 168 | D2: 160 | E2: 167 | F2: 195 | G2: 200 | H2: 196 | I2: 184 | J2: 0 | K2: =SUM(D2:J2) -> 1102
A3: 119973 | B3: Agus Elementary School | C3: 235 | D3: 224 | E3: 191 | F3: 199 | G3: 205 | H3: 236 | I3: 202 | J3: 0 | K3: =SUM(D3:J3) -> 1257
A4: 119985 | B4: Babag I Elementary School | C4: 261 | D4: 249 | E4: 265 | F4: 294 | G4: 337 | H4: 309 | I4: 305 | J4: 0 | K4: =SUM(D4:J4) -> 1759
A5: 119986 | B5: Babag II Elementary School | C5: 197 | D5: 188 | E5: 204 | F5: 235 | G5: 227 | H5: 284 | I5: 220 | J5: 0 | K5: =SUM(D5:J5) -> 1358
A6: 119974 | B6: Bagong Silang Elementary School | C6: 217 | D6: 207 | E6: 209 | F6: 221 | G6: 225 | H6: 244 | I6: 201 | J6: 0 | K6: =SUM(D6:J6) -> 1307
A7: 119963 | B7: Bankal Elementary School | C7: 507 | D7: 483 | E7: 450 | F7: 498 | G7: 526 | H7: 607 | I7: 566 | J7: 0 | K7: =SUM(D7:J7) -> 3130
A8: 119950 | B8: Baring Elementary School | C8: 110 | D8: 105 | E8: 71 | F8: 93 | G8: 94 | H8: 71 | I8: 90 | J8: 0 | K8: =SUM(D8:J8) -> 524
A9: 119975 | B9: Basak Elementary School | C9: 309 | D9: 294 | E9: 244 | F9: 309 | G9: 281 | H9: 345 | I9: 282 | J9: 0 | K9: =SUM(D9:J9) -> 1755
A10: 119964 | B10: Buaya Elementary School | C10: 247 | D10: 235 | E10: 233 | F10: 243 | G10: 229 | H10: 293 | I10: 234 | J10: 0 | K10: =SUM(D10:J10) -> 1467
A11: 119976 | B11: Buyong Elementary School | C11: 231 | D11: 220 | E11: 168 | F11: 194 | G11: 202 | H11: 203 | I11: 192 | J11: 0 | K11: =SUM(D11:J11) -> 1179
A12: 119951 | B12: Candagsao Elementary School | C12: 55 | D12: 52 | E12: 45 | F12: 45 | G12: 40 | H12: 49 | I12: 44 | J12: 0 | K12: =SUM(D12:J12) -> 275
A13: 119987 | B13: Canjulao Elementary School | C13: 196 | D13: 187 | E13: 169 | F13: 171 | G13: 199 | H13: 214 | I13: 198 | J13: 0 | K13: =SUM(D13:J13) -> 1138
... A45: 119962 | B45: Tungasan Elementary School | C45: 53 | D45: 50 | E45: 56 | F45: 60 | G45: 53 | H45: 60 | I45: 61 | J45: 0 | K45: =SUM(D45:J45) -> 340
A46: #N/A | B46: Grand Total | C46: =SUM(C2:C45) -> 8737 | D46: =SUM(D2:D45) -> 8321 | E46: =SUM(E2:E45) -> 7635 | F46: =SUM(F2:F45) -> 8731 | G46: =SUM(G2:G45) -> 8653 | H46: =SUM(H2:H45) -> 9394 | I46: =SUM(I2:I45) -> 8690 | J46: =SUM(J2:J45) -> 362 | K46: =SUM(K2:K45) -> 51786
A49: Note: | B49: Data of the Enrollment was based on the LIS system as of May 21, 2026.

Sheet Elem_
A1: UPDATED TEACHER'S NEED ANALYSIS | AK1: =SUM(AJ9:AJ53) -> 51 | AX1: As of 08/05/2026 | BA1: As of 09/1/2026 | BD1: As of 10/14/2026
A5: as of May 2026
B6: Class Size | M6: 50-60 | N6: 30-35 | O6: 30-35 | P6: 30-35 | Q6: 40-45 | R6: 40-45 | S6: 40-45 | T6: 15 | U6: 55 | V6: 33 | W6: 33 | X6: 33 | Y6: 43 | Z6: 43 | AA6: 43 | AB6: 15 | AR6: 48 | AX6: 15
A7: School | B7: Elementary School | C7: District | D7: Enrolment (SY 2025-2026)-as of May 21, 2026 | M7: Class Size | U7: Number of Sections/Classes | AD7: Teachers as of May 2026 | AL7: 51 | AN7: 50 | AR7: =AR6/AI55 -> 0.40336134 | AV7: Needs (after the deployment) | AX7: =AX6/AV55 -> 0.20547945 | BA7: Needs (after the deployment) | BD7: Needs (after the deployment)
D8: K | E8: G1 | F8: G2 | G8: G3 | H8: G4 | I8: G5 | J8: G6 | K8: NG | L8: TOTAL | M8: K | N8: G1 | O8: G2 | P8: G3 | Q8: G4 | R8: G5 | S8: G6 | T8: TOTAL | U8: K | V8: G1 | W8: G2 | X8: G3 | Y8: G4 | Z8: G5 | AA8: G6 | AB8: NG | AC8: TOTAL | AD8: Required | AE8: Existing | AF8: GAP | AG8: T-Out | AH8: T-In | AI8: Needs | AJ8: Deployment | AL8: 122 | AN8: delployment 50 items | AO8: =AN7/AI55 -> 0.42016807 | AP8: Transfers | AQ8: final allocation | AR8: ofr 48 item only | AT8: Allocation | AU8: Deployment | AY8: Allocation | AZ8: Deployment | BB8: Allocation | BC8: Deployment
A9: 119964 | B9: Buaya ES | C9: 1 | D9: 247 | E9: 235 | F9: 233 | G9: 243 | H9: 229 | I9: 293 | J9: 234 | K9: 0 | L9: 1714 | M9: 49 | N9: 29 | O9: 29 | P9: 30 | Q9: 38 | R9: 42 | S9: 39 | T9: 256 | U9: 5 | V9: 8 | W9: 8 | X9: 8 | Y9: 6 | Z9: 7 | AA9: 6 | AB9: 0 | AC9: 48 | AD9: 54.75 | AE9: 51 | AF9: 4 | AG9: =COUNTIF(Transfer!E:E,Elem_!B9) -> 2 | AH9: =COUNTIF(Transfer!H:H,Elem_!B9) -> 1 | AI9: =AF9+AG9-AH9 -> 5 | AJ9: 2 | AK9: 5 | AL9: =ROUND(AK9*$AL$7/$AL$8,0) -> 2 | AN9: =AI9*0.42 -> 2.1 | AP9: transferred out 1 | AQ9: 3 | AR9: =AI9*0.4 -> 2 | AT9: 2 | AU9: 3 | AV9: =AI9-AU9 -> 2 | AW9: =AI9-AR9 -> 3 | AX9: =AV9*0.2 -> 0.4 | BA9: =AV9-AZ9 -> 2 | BB9: 2 | BC9: 2 | BD9: =BA9-BC9 -> 0
A10: 119986 | B10: Babag II ES | C10: 8 | D10: 197 | E10: 188 | F10: 204 | G10: 235 | H10: 227 | I10: 284 | J10: 220 | K10: 0 | L10: 1555 | M10: 49 | N10: 31 | O10: 29 | P10: 29 | Q10: 38 | R10: 41 | S10: 37 | T10: 254 | U10: 4 | V10: 6 | W10: 7 | X10: 8 | Y10: 6 | Z10: 7 | AA10: 6 | AB10: 0 | AC10: 44 | AD10: 50.75 | AE10: 43 | AF10: 8 | AG10: =COUNTIF(Transfer!E:E,Elem_!B10) -> 0 | AH10: =COUNTIF(Transfer!H:H,Elem_!B10) -> 2 | AI10: =AF10+AG10-AH10 -> 6 | AJ10: 2 | AK10: 6 | AL10: =ROUND(AK10*$AL$7/$AL$8,0) -> 3 | AN10: =AI10*0.42 -> 2.52 | AP10: transferred in 1 | AQ10: 2 | AR10: =AI10*0.4 -> 2.4 | AT10: 3 | AU10: 2 | AV10: =AI10-AU10 -> 4 | AW10: =AI10-AR10 -> 3.6 | AX10: =AV10*0.2 -> 0.8 | AY10: 1 | AZ10: 1 | BA10: =AV10-AZ10 -> 3 | BD10: =BA10-BC10 -> 3
A11: 119974 | B11: Bagong Silang ES | C11: 4 | D11: 217 | E11: 207 | F11: 209 | G11: 221 | H11: 225 | I11: 244 | J11: 201 | K11: 0 | L11: 1524 | M11: 54 | N11: 30 | O11: 30 | P11: 32 | Q11: 38 | R11: 41 | S11: 40 | T11: 265 | U11: 4 | V11: 7 | W11: 7 | X11: 7 | Y11: 6 | Z11: 6 | AA11: 5 | AB11: 0 | AC11: 42 | AD11: 48 | AE11: 49 | AF11: -1 | AG11: =COUNTIF(Transfer!E:E,Elem_!B11) -> 0 | AH11: =COUNTIF(Transfer!H:H,Elem_!B11) -> 0 | AI11: =AF11+AG11-AH11 -> -1 | AJ11: 0 | AL11: =ROUND(AK11*$AL$7/$AL$8,0) -> 0 | AN11: =AI11*0.42 -> -0.42 | AQ11: 0 | AR11: =AI11*0.4 -> -0.4 | AV11: =AI11-AU11 -> -1 | AW11: =AI11-AR11 -> -0.6 | AX11: =AV11*0.2 -> -0.2 | BA11: =AV11-AZ11 -> -1 | BD11: =BA11-BC11 -> -1
B12: Basak ES | C12: 6 | D12: 309 | E12: 294 | F12: 244 | G12: 309 | H12: 281 | I12: 345 | J12: 282 | K12: 0 | L12: 2064 | M12: 52 | N12: 33 | O12: 31 | P12: 31 | Q12: 40 | R12: 38 | S12: 40 | T12: 265 | U12: 6 | V12: 9 | W12: 8 | X12: 10 | Y12: 7 | Z12: 9 | AA12: 7 | AB12: 0 | AC12: 56 | AD12: 64.25 | AE12: 59 | AF12: 5 | AG12: =COUNTIF(Transfer!E:E,Elem_!B12) -> 0 | AH12: =COUNTIF(Transfer!H:H,Elem_!B12) -> 0 | AI12: =AF12+AG12-AH12 -> 5 | AJ12: 2 | AK12: 5 | AL12: =ROUND(AK12*$AL$7/$AL$8,0) -> 2 | AN12: =AI12*0.42 -> 2.1 | AQ12: 2 | AR12: =AI12*0.4 -> 2 | AT12: 2 | AU12: 2 | AV12: =AI12-AU12 -> 3 | AW12: =AI12-AR12 -> 3 | AX12: =AV12*0.2 -> 0.6 | AY12: 1 | AZ12: 1 | BA12: =AV12-AZ12 -> 2 | BD12: =BA12-BC12 -> 2
A13: 119978 | B13: Maribago ES | C13: 4 | D13: 235 | E13: 224 | F13: 229 | G13: 237 | H13: 235 | I13: 289 | J13: 274 | K13: 0 | L13: 1723 | M13: 47 | N13: 32 | O13: 33 | P13: 30 | Q13: 39 | R13: 41 | S13: 39 | T13: 261 | U13: 5 | V13: 7 | W13: 7 | X13: 8 | Y13: 6 | Z13: 7 | AA13: 7 | AB13: 0 | AC13: 47 | AD13: 54 | AE13: 50 | AF13: 4 | AG13: =COUNTIF(Transfer!E:E,Elem_!B13) -> 1 | AH13: =COUNTIF(Transfer!H:H,Elem_!B13) -> 0 | AI13: =AF13+AG13-AH13 -> 5 | AJ13: 2 | AK13: 5 | AL13: =ROUND(AK13*$AL$7/$AL$8,0) -> 2 | AN13: =AI13*0.42 -> 2.1 | AQ13: 2 | AR13: =AI13*0.4 -> 2 | AT13: 2 | AU13: 2 | AV13: =AI13-AU13 -> 3 | AW13: =AI13-AR13 -> 3 | AX13: =AV13*0.2 -> 0.6 | AY13: 1 | AZ13: 2 | BA13: =AV13-AZ13 -> 1 | BD13: =BA13-BC13 -> 1
A14: 119985 | B14: Babag I ES | C14: 8 | D14: 261 | E14: 249 | F14: 265 | G14: 294 | H14: 337 | I14: 309 | J14: 305 | K14: 0 | L14: 2020 | M14: 52 | N14: 31 | O14: 29 | P14: 33 | Q14: 42 | R14: 39 | S14: 38 | T14: 264 | U14: 5 | V14: 8 | W14: 9 | X14: 9 | Y14: 8 | Z14: 8 | AA14: 8 | AB14: 0 | AC14: 55 | AD14: 63.25 | AE14: 69 | AF14: -6 | AG14: =COUNTIF(Transfer!E:E,Elem_!B14) -> 0 | AH14: =COUNTIF(Transfer!H:H,Elem_!B14) -> 0 | AI14: =AF14+AG14-AH14 -> -6 | AJ14: 0 | AL14: =ROUND(AK14*$AL$7/$AL$8,0) -> 0 | AN14: =AI14*0.42 -> -2.52 | AQ14: -3 | AR14: =AI14*0.4 -> -2.4 | AV14: =AI14-AU14 -> -6 | AW14: =AI14-AR14 -> -3.6 | AX14: =AV14*0.2 -> -1.2 | BA14: =AV14-AZ14 -> -6 | BD14: =BA14-BC14 -> -6
A15: 119984 | B15: Sudtonggan ES | C15: 6 | D15: 237 | E15: 226 | F15: 192 | G15: 215 | H15: 270 | I15: 255 | J15: 223 | K15: 0 | L15: 1618 | M15: 47 | N15: 32 | O15: 32 | P15: 31 | Q15: 39 | R15: 43 | S15: 37 | T15: 261 | U15: 5 | V15: 7 | W15: 6 | X15: 7 | Y15: 7 | Z15: 6 | AA15: 6 | AB15: 0 | AC15: 44 | AD15: 50.5 | AE15: 49 | AF15: 2 | AG15: =COUNTIF(Transfer!E:E,Elem_!B15) -> 0 | AH15: =COUNTIF(Transfer!H:H,Elem_!B15) -> 0 | AI15: =AF15+AG15-AH15 -> 2 | AJ15: 1 | AK15: 2 | AL15: =ROUND(AK15*$AL$7/$AL$8,0) -> 1 | AN15: =AI15*0.42 -> 0.84 | AP15: transferred in 1 | AQ15: 0 | AR15: =AI15*0.4 -> 0.8 | AT15: 1 | AV15: =AI15-AU15 -> 2 | AW15: =AI15-AR15 -> 1.2 | AX15: =AV15*0.2 -> 0.4 | BA15: =AV15-AZ15 -> 2 | BD15: =BA15-BC15 -> 2
A16: 119968 | B16: Pajo ES | C16: 3 | D16: 278 | E16: 265 | F16: 237 | G16: 247 | H16: 285 | I16: 281 | J16: 254 | K16: 0 | L16: 1847 | M16: 46 | N16: 29 | O16: 30 | P16: 31 | Q16: 41 | R16: 40 | S16: 42 | T16: 259 | U16: 6 | V16: 9 | W16: 8 | X16: 8 | Y16: 7 | Z16: 7 | AA16: 6 | AB16: 0 | AC16: 51 | AD16: 58 | AE16: 49 | AF16: 9 | AG16: =COUNTIF(Transfer!E:E,Elem_!B16) -> 0 | AH16: =COUNTIF(Transfer!H:H,Elem_!B16) -> 0 | AI16: =AF16+AG16-AH16 -> 9 | AJ16: 4 | AK16: 9 | AL16: =ROUND(AK16*$AL$7/$AL$8,0) -> 4 | AN16: =AI16*0.42 -> 3.78 | AQ16: 4 | AR16: =AI16*0.4 -> 3.6 | AT16: 4 | AU16: 4 | AV16: =AI16-AU16 -> 5 | AW16: =AI16-AR16 -> 5.4 | AX16: =AV16*0.2 -> 1 | AY16: 1 | AZ16: 1 | BA16: =AV16-AZ16 -> 4 | BB16: 1 | BC16: 1 | BD16: =BA16-BC16 -> 3
A17: 119972 | B17: Abuno ES | C17: 4 | D17: 168 | E17: 160 | F17: 167 | G17: 195 | H17: 200 | I17: 196 | J17: 184 | K17: 0 | L17: 1270 | M17: 42 | N17: 32 | O17: 28 | P17: 33 | Q17: 40 | R17: 39 | S17: 37 | T17: 251 | U17: 4 | V17: 5 | W17: 6 | X17: 6 | Y17: 5 | Z17: 5 | AA17: 5 | AB17: 0 | AC17: 36 | AD17: 41.25 | AE17: 40 | AF17: 1 | AG17: =COUNTIF(Transfer!E:E,Elem_!B17) -> 0 | AH17: =COUNTIF(Transfer!H:H,Elem_!B17) -> 0 | AI17: =AF17+AG17-AH17 -> 1 | AJ17: 0 | AL17: =ROUND(AK17*$AL$7/$AL$8,0) -> 0 | AN17: =AI17*0.42 -> 0.42 | AQ17: 0 | AR17: =AI17*0.4 -> 0.4 | AV17: =AI17-AU17 -> 1 | AW17: =AI17-AR17 -> 0.6 | AX17: =AV17*0.2 -> 0.2 | BA17: =AV17-AZ17 -> 1 | BB17: 1 | BC17: 1 | BD17: =BA17-BC17 -> 0
A18: 119960 | B18: Talima ES | C18: 10 | D18: 149 | E18: 142 | F18: 126 | G18: 126 | H18: 105 | I18: 117 | J18: 136 | K18: 0 | L18: 901 | M18: 50 | N18: 28 | O18: 32 | P18: 32 | Q18: 35 | R18: 39 | S18: 34 | T18: 250 | U18: 3 | V18: 5 | W18: 4 | X18: 4 | Y18: 3 | Z18: 3 | AA18: 4 | AB18: 0 | AC18: 26 | AD18: 29.5 | AE18: 28 | AF18: 2 | AG18: =COUNTIF(Transfer!E:E,Elem_!B18) -> 0 | AH18: =COUNTIF(Transfer!H:H,Elem_!B18) -> 0 | AI18: =AF18+AG18-AH18 -> 2 | AJ18: 1 | AK18: 2 | AL18: =ROUND(AK18*$AL$7/$AL$8,0) -> 1 | AN18: =AI18*0.42 -> 0.84 | AQ18: 1 | AR18: =AI18*0.4 -> 0.8 | AU18: 1 | AV18: =AI18-AU18 -> 1 | AW18: =AI18-AR18 -> 1.2 | AX18: =AV18*0.2 -> 0.2 | BA18: =AV18-AZ18 -> 1 | BD18: =BA18-BC18 -> 1
A19: 119970 | B19: Pusok ES | C19: 3 | D19: 342 | E19: 326 | F19: 285 | G19: 342 | H19: 343 | I19: 423 | J19: 369 | K19: 0 | L19: 2430 | M19: 49 | N19: 33 | O19: 32 | P19: 31 | Q19: 43 | R19: 42 | S19: 41 | T19: 271 | U19: 7 | V19: 10 | W19: 9 | X19: 11 | Y19: 8 | Z19: 10 | AA19: 9 | AB19: 0 | AC19: 64 | AD19: 73.5 | AE19: 73 | AF19: 1 | AG19: =COUNTIF(Transfer!E:E,Elem_!B19) -> 0 | AH19: =COUNTIF(Transfer!H:H,Elem_!B19) -> 1 | AI19: =AF19+AG19-AH19 -> 0 | AJ19: 0 | AL19: =ROUND(AK19*$AL$7/$AL$8,0) -> 0 | AN19: =AI19*0.42 -> 0 | AQ19: 0 | AR19: =AI19*0.4 -> 0 | AV19: =AI19-AU19 -> 0 | AW19: =AI19-AR19 -> 0 | AX19: =AV19*0.2 -> 0 | BA19: =AV19-AZ19 -> 0 | BD19: =BA19-BC19 -> 0
A20: 119963 | B20: Bankal ES | C20: 2 | D20: 507 | E20: 483 | F20: 450 | G20: 498 | H20: 526 | I20: 607 | J20: 566 | K20: 0 | L20: 3637 | M20: 51 | N20: 32 | O20: 32 | P20: 31 | Q20: 40 | R20: 40 | S20: 40 | T20: 266 | U20: 10 | V20: 15 | W20: 14 | X20: 16 | Y20: 13 | Z20: 15 | AA20: 14 | AB20: 0 | AC20: 97 | AD20: 111.5 | AE20: 105 | AF20: 7 | AG20: =COUNTIF(Transfer!E:E,Elem_!B20) -> 1 | AH20: =COUNTIF(Transfer!H:H,Elem_!B20) -> 1 | AI20: =AF20+AG20-AH20 -> 7 | AJ20: 2 | AK20: 7 | AL20: =ROUND(AK20*$AL$7/$AL$8,0) -> 3 | AN20: =AI20*0.42 -> 2.94 | AP20: transferred in 1 | AQ20: 2 | AR20: =AI20*0.4 -> 2.8 | AT20: 2 | AU20: 1 | AV20: =AI20-AU20 -> 6 | AW20: =AI20-AR20 -> 4.2 | AX20: =AV20*0.2 -> 1.2 | AY20: 1 | AZ20: 1 | BA20: =AV20-AZ20 -> 5 | BB20: 1 | BC20: 1 | BD20: =BA20-BC20 -> 4
A21: 119983 | B21: Suba-Masulog ES | C21: 6 | D21: 248 | E21: 236 | F21: 214 | G21: 237 | H21: 232 | I21: 281 | J21: 223 | K21: 0 | L21: 1671 | M21: 50 | N21: 30 | O21: 31 | P21: 30 | Q21: 39 | R21: 40 | S21: 37 | T21: 257 | U21: 5 | V21: 8 | W21: 7 | X21: 8 | Y21: 6 | Z21: 7 | AA21: 6 | AB21: 0 | AC21: 47 | AD21: 53.75 | AE21: 50 | AF21: 4 | AG21: =COUNTIF(Transfer!E:E,Elem_!B21) -> 0 | AH21: =COUNTIF(Transfer!H:H,Elem_!B21) -> 0 | AI21: =AF21+AG21-AH21 -> 4 | AJ21: 1 | AK21: 4 | AL21: =ROUND(AK21*$AL$7/$AL$8,0) -> 2 | AN21: =AI21*0.42 -> 1.68 | AQ21: 2 | AR21: =AI21*0.4 -> 1.6 | AT21: 1 | AU21: 1 | AV21: =AI21-AU21 -> 3 | AW21: =AI21-AR21 -> 2.4 | AX21: =AV21*0.2 -> 0.6 | AY21: 1 | AZ21: 1 | BA21: =AV21-AZ21 -> 2 | BD21: =BA21-BC21 -> 2
A22: 119973 | B22: Agus ES | C22: 4 | D22: 235 | E22: 224 | F22: 191 | G22: 199 | H22: 205 | I22: 236 | J22: 202 | K22: 0 | L22: 1492 | M22: 47 | N22: 32 | O22: 32 | P22: 28 | Q22: 41 | R22: 39 | S22: 40 | T22: 259 | U22: 5 | V22: 7 | W22: 6 | X22: 7 | Y22: 5 | Z22: 6 | AA22: 5 | AB22: 0 | AC22: 41 | AD22: 46.75 | AE22: 42 | AF22: 5 | AG22: =COUNTIF(Transfer!E:E,Elem_!B22) -> 0 | AH22: =COUNTIF(Transfer!H:H,Elem_!B22) -> 0 | AI22: =AF22+AG22-AH22 -> 5 | AJ22: 2 | AK22: 5 | AL22: =ROUND(AK22*$AL$7/$AL$8,0) -> 2 | AN22: =AI22*0.42 -> 2.1 | AQ22: 2 | AR22: =AI22*0.4 -> 2 | AT22: 2 | AU22: 2 | AV22: =AI22-AU22 -> 3 | AW22: =AI22-AR22 -> 3 | AX22: =AV22*0.2 -> 0.6 | AY22: 1 | AZ22: 1 | BA22: =AV22-AZ22 -> 2 | BD22: =BA22-BC22 -> 2
A23: 119976 | B23: Buyong ES | C23: 4 | D23: 231 | E23: 220 | F23: 168 | G23: 194 | H23: 202 | I23: 203 | J23: 192 | K23: 0 | L23: 1410 | M23: 46 | N23: 31 | O23: 28 | P23: 32 | Q23: 40 | R23: 41 | S23: 38 | T23: 256 | U23: 5 | V23: 7 | W23: 6 | X23: 6 | Y23: 5 | Z23: 5 | AA23: 5 | AB23: 0 | AC23: 39 | AD23: 44.25 | AE23: 39 | AF23: 5 | AG23: =COUNTIF(Transfer!E:E,Elem_!B23) -> 2 | AH23: =COUNTIF(Transfer!H:H,Elem_!B23) -> 0 | AI23: =AF23+AG23-AH23 -> 7 | AJ23: 2 | AK23: 7 | AL23: =ROUND(AK23*$AL$7/$AL$8,0) -> 3 | AN23: =AI23*0.42 -> 2.94 | AP23: transferred out 1 | AQ23: 4 | AR23: =AI23*0.4 -> 2.8 | AT23: 3 | AU23: 4 | AV23: =AI23-AU23 -> 3 | AW23: =AI23-AR23 -> 4.2 | AX23: =AV23*0.2 -> 0.6 | AY23: 1 | AZ23: 1 | BA23: =AV23-AZ23 -> 2 | BD23: =BA23-BC23 -> 2
A24: 119958 | B24: Sta. Rosa ES | C24: 9 | D24: 121 | E24: 115 | F24: 117 | G24: 119 | H24: 109 | I24: 114 | J24: 150 | K24: 0 | L24: 845 | M24: 40 | N24: 29 | O24: 29 | P24: 30 | Q24: 36 | R24: 38 | S24: 38 | T24: 240 | U24: 3 | V24: 4 | W24: 4 | X24: 4 | Y24: 3 | Z24: 3 | AA24: 4 | AB24: 0 | AC24: 25 | AD24: 28.5 | AE24: 25 | AF24: 4 | AG24: =COUNTIF(Transfer!E:E,Elem_!B24) -> 0 | AH24: =COUNTIF(Transfer!H:H,Elem_!B24) -> 0 | AI24: =AF24+AG24-AH24 -> 4 | AJ24: 1 | AK24: 4 | AL24: =ROUND(AK24*$AL$7/$AL$8,0) -> 2 | AN24: =AI24*0.42 -> 1.68 | AQ24: 2 | AR24: =AI24*0.4 -> 1.6 | AT24: 2 | AU24: 2 | AV24: =AI24-AU24 -> 2 | AW24: =AI24-AR24 -> 2.4 | AX24: =AV24*0.2 -> 0.4 | BA24: =AV24-AZ24 -> 2 | BB24: 1 | BC24: 1 | BD24: =BA24-BC24 -> 1
A25: 119957 | B25: Sabang ES | C25: 9 | D25: 156 | E25: 149 | F25: 129 | G25: 143 | H25: 157 | I25: 142 | J25: 138 | K25: 0 | L25: 1014 | M25: 52 | N25: 30 | O25: 32 | P25: 29 | Q25: 39 | R25: 36 | S25: 35 | T25: 253 | U25: 3 | V25: 5 | W25: 4 | X25: 5 | Y25: 4 | Z25: 4 | AA25: 4 | AB25: 0 | AC25: 29 | AD25: 33.25 | AE25: 31 | AF25: 2 | AG25: =COUNTIF(Transfer!E:E,Elem_!B25) -> 0 | AH25: =COUNTIF(Transfer!H:H,Elem_!B25) -> 0 | AI25: =AF25+AG25-AH25 -> 2 | AJ25: 1 | AK25: 2 | AL25: =ROUND(AK25*$AL$7/$AL$8,0) -> 1 | AN25: =AI25*0.42 -> 0.84 | AQ25: 1 | AR25: =AI25*0.4 -> 0.8 | AT25: 1 | AU25: 1 | AV25: =AI25-AU25 -> 1 | AW25: =AI25-AR25 -> 1.2 | AX25: =AV25*0.2 -> 0.2 | BA25: =AV25-AZ25 -> 1 | BD25: =BA25-BC25 -> 1
A26: 119993 | B26: Timpolok ES | C26: 7 | D26: 79 | E26: 75 | F26: 84 | G26: 104 | H26: 108 | I26: 79 | J26: 101 | K26: 0 | L26: 630 | M26: 40 | N26: 25 | O26: 28 | P26: 26 | Q26: 36 | R26: 40 | S26: 34 | T26: 229 | U26: 2 | V26: 3 | W26: 3 | X26: 4 | Y26: 3 | Z26: 2 | AA26: 3 | AB26: 0 | AC26: 20 | AD26: 23 | AE26: 23 | AF26: 0 | AG26: =COUNTIF(Transfer!E:E,Elem_!B26) -> 0 | AH26: =COUNTIF(Transfer!H:H,Elem_!B26) -> 0 | AI26: =AF26+AG26-AH26 -> 0 | AJ26: 0 | AL26: =ROUND(AK26*$AL$7/$AL$8,0) -> 0 | AN26: =AI26*0.42 -> 0 | AQ26: 0 | AR26: =AI26*0.4 -> 0 | AV26: =AI26-AU26 -> 0 | AW26: =AI26-AR26 -> 0 | AX26: =AV26*0.2 -> 0 | BA26: =AV26-AZ26 -> 0 | BD26: =BA26-BC26 -> 0
A27: 119980 | B27: Pajac ES | C27: 4 | D27: 186 | E27: 177 | F27: 130 | G27: 134 | H27: 148 | I27: 161 | J27: 138 | K27: 0 | L27: 1074 | M27: 47 | N27: 30 | O27: 33 | P27: 27 | Q27: 37 | R27: 40 | S27: 35 | T27: 249 | U27: 4 | V27: 6 | W27: 4 | X27: 5 | Y27: 4 | Z27: 4 | AA27: 4 | AB27: 0 | AC27: 31 | AD27: 35.25 | AE27: 31 | AF27: 4 | AG27: =COUNTIF(Transfer!E:E,Elem_!B27) -> 0 | AH27: =COUNTIF(Transfer!H:H,Elem_!B27) -> 1 | AI27: =AF27+AG27-AH27 -> 3 | AJ27: 1 | AK27: 3 | AL27: =ROUND(AK27*$AL$7/$AL$8,0) -> 1 | AN27: =AI27*0.42 -> 1.26 | AP27: transferred in 1 | AQ27: 0 | AR27: =AI27*0.4 -> 1.2 | AT27: 1 | AV27: =AI27-AU27 -> 3 | AW27: =AI27-AR27 -> 1.8 | AX27: =AV27*0.2 -> 0.6 | AY27: 1 | AZ27: 1 | BA27: =AV27-AZ27 -> 2 | BD27: =BA27-BC27 -> 2
A28: 119952 | B28: FFMM ES | C28: 10 | D28: 44 | E28: 42 | F28: 34 | G28: 60 | H28: 51 | I28: 47 | J28: 67 | K28: 0 | L28: 345 | M28: 44 | N28: 21 | O28: 17 | P28: 30 | Q28: 26 | R28: 24 | S28: 34 | T28: 196 | U28: 1 | V28: 2 | W28: 2 | X28: 2 | Y28: 2 | Z28: 2 | AA28: 2 | AB28: 0 | AC28: 13 | AD28: 15 | AE28: 14 | AF28: 1 | AG28: =COUNTIF(Transfer!E:E,Elem_!B28) -> 0 | AH28: =COUNTIF(Transfer!H:H,Elem_!B28) -> 0 | AI28: =AF28+AG28-AH28 -> 1 | AJ28: 0 | AL28: =ROUND(AK28*$AL$7/$AL$8,0) -> 0 | AN28: =AI28*0.42 -> 0.42 | AQ28: 0 | AR28: =AI28*0.4 -> 0.4 | AV28: =AI28-AU28 -> 1 | AW28: =AI28-AR28 -> 0.6 | AX28: =AV28*0.2 -> 0.2 | BA28: =AV28-AZ28 -> 1 | BD28: =BA28-BC28 -> 1
A29: 119992 | B29: Tiangue ES | C29: 8 | D29: 36 | E29: 34 | F29: 40 | G29: 43 | H29: 43 | I29: 46 | J29: 32 | K29: 0 | L29: 274 | M29: 36 | N29: 17 | O29: 20 | P29: 22 | Q29: 43 | R29: 23 | S29: 32 | T29: 193 | U29: 1 | V29: 2 | W29: 2 | X29: 2 | Y29: 1 | Z29: 2 | AA29: 1 | AB29: 0 | AC29: 11 | AD29: 12.5 | AE29: 12 | AF29: 1 | AG29: =COUNTIF(Transfer!E:E,Elem_!B29) -> 1 | AH29: =COUNTIF(Transfer!H:H,Elem_!B29) -> 0 | AI29: =AF29+AG29-AH29 -> 2 | AJ29: 1 | AK29: 2 | AL29: =ROUND(AK29*$AL$7/$AL$8,0) -> 1 | AN29: =AI29*0.42 -> 0.84 | AP29: transferred out 1 | AQ29: 2 | AR29: =AI29*0.4 -> 0.8 | AT29: 1 | AU29: 2 | AV29: =AI29-AU29 -> 0 | AW29: =AI29-AR29 -> 1.2 | AX29: =AV29*0.2 -> 0 | BA29: =AV29-AZ29 -> 0 | BD29: =BA29-BC29 -> 0
A30: 119951 | B30: Candagsao ES | C30: 10 | D30: 55 | E30: 52 | F30: 45 | G30: 45 | H30: 40 | I30: 49 | J30: 44 | K30: 0 | L30: 330 | M30: 55 | N30: 26 | O30: 23 | P30: 23 | Q30: 40 | R30: 25 | S30: 22 | T30: 214 | U30: 1 | V30: 2 | W30: 2 | X30: 2 | Y30: 1 | Z30: 2 | AA30: 2 | AB30: 0 | AC30: 12 | AD30: 13.75 | AE30: 13 | AF30: 1 | AG30: =COUNTIF(Transfer!E:E,Elem_!B30) -> 0 | AH30: =COUNTIF(Transfer!H:H,Elem_!B30) -> 0 | AI30: =AF30+AG30-AH30 -> 1 | AJ30: 0 | AL30: =ROUND(AK30*$AL$7/$AL$8,0) -> 0 | AN30: =AI30*0.42 -> 0.42 | AQ30: 0 | AR30: =AI30*0.4 -> 0.4 | AV30: =AI30-AU30 -> 1 | AW30: =AI30-AR30 -> 0.6 | AX30: =AV30*0.2 -> 0.2 | BA30: =AV30-AZ30 -> 1 | BD30: =BA30-BC30 -> 1
A31: 119971 | B31: Soong ES | C31: 2 | D31: 436 | E31: 415 | F31: 371 | G31: 421 | H31: 415 | I31: 450 | J31: 437 | K31: 0 | L31: 2945 | M31: 55 | N31: 32 | O31: 31 | P31: 32 | Q31: 42 | R31: 41 | S31: 40 | T31: 273 | U31: 8 | V31: 13 | W31: 12 | X31: 13 | Y31: 10 | Z31: 11 | AA31: 11 | AB31: 0 | AC31: 78 | AD31: 89.25 | AE31: 83 | AF31: 6 | AG31: =COUNTIF(Transfer!E:E,Elem_!B31) -> 1 | AH31: =COUNTIF(Transfer!H:H,Elem_!B31) -> 0 | AI31: =AF31+AG31-AH31 -> 7 | AJ31: 2 | AK31: 7 | AL31: =ROUND(AK31*$AL$7/$AL$8,0) -> 3 | AN31: =AI31*0.42 -> 2.94 | AP31: transferred out 1 | AQ31: 4 | AR31: =AI31*0.4 -> 2.8 | AT31: 3 | AU31: 4 | AV31: =AI31-AU31 -> 3 | AW31: =AI31-AR31 -> 4.2 | AX31: =AV31*0.2 -> 0.6 | BA31: =AV31-AZ31 -> 3 | BB31: 1 | BC31: 1 | BD31: =BA31-BC31 -> 2
A32: 119969 | B32: Punta Engaño ES | C32: 2 | D32: 240 | E32: 229 | F32: 197 | G32: 221 | H32: 254 | I32: 199 | J32: 218 | K32: 0 | L32: 1558 | M32: 48 | N32: 33 | O32: 33 | P32: 32 | Q32: 42 | R32: 40 | S32: 36 | T32: 264 | U32: 5 | V32: 7 | W32: 6 | X32: 7 | Y32: 6 | Z32: 5 | AA32: 6 | AB32: 0 | AC32: 42 | AD32: 48 | AE32: 46 | AF32: 2 | AG32: =COUNTIF(Transfer!E:E,Elem_!B32) -> 0 | AH32: =COUNTIF(Transfer!H:H,Elem_!B32) -> 0 | AI32: =AF32+AG32-AH32 -> 2 | AJ32: 1 | AK32: 2 | AL32: =ROUND(AK32*$AL$7/$AL$8,0) -> 1 | AN32: =AI32*0.42 -> 0.84 | AQ32: 1 | AR32: =AI32*0.4 -> 0.8 | AT32: 1 | AU32: 1 | AV32: =AI32-AU32 -> 1 | AW32: =AI32-AR32 -> 1.2 | AX32: =AV32*0.2 -> 0.2 | BA32: =AV32-AZ32 -> 1 | BD32: =BA32-BC32 -> 1
A33: 119990 | B33: Lo-ok ES | C33: 7 | D33: 143 | E33: 136 | F33: 121 | G33: 177 | H33: 154 | I33: 164 | J33: 134 | K33: 0 | L33: 1029 | M33: 48 | N33: 27 | O33: 30 | P33: 30 | Q33: 39 | R33: 41 | S33: 34 | T33: 249 | U33: 3 | V33: 5 | W33: 4 | X33: 6 | Y33: 4 | Z33: 4 | AA33: 4 | AB33: 0 | AC33: 30 | AD33: 34.5 | AE33: 32 | AF33: 3 | AG33: =COUNTIF(Transfer!E:E,Elem_!B33) -> 0 | AH33: =COUNTIF(Transfer!H:H,Elem_!B33) -> 0 | AI33: =AF33+AG33-AH33 -> 3 | AJ33: 1 | AK33: 3 | AL33: =ROUND(AK33*$AL$7/$AL$8,0) -> 1 | AN33: =AI33*0.42 -> 1.26 | AQ33: 1 | AR33: =AI33*0.4 -> 1.2 | AT33: 1 | AU33: 1 | AV33: =AI33-AU33 -> 2 | AW33: =AI33-AR33 -> 1.8 | AX33: =AV33*0.2 -> 0.4 | AY33: 1 | AZ33: 1 | BA33: =AV33-AZ33 -> 1 | BD33: =BA33-BC33 -> 1
A34: 119956 | B34: Poo ES | C34: 9 | D34: 126 | E34: 120 | F34: 94 | G34: 112 | H34: 109 | I34: 92 | J34: 100 | K34: 0 | L34: 753 | M34: 42 | N34: 30 | O34: 31 | P34: 28 | Q34: 36 | R34: 31 | S34: 33 | T34: 231 | U34: 3 | V34: 4 | W34: 3 | X34: 4 | Y34: 3 | Z34: 3 | AA34: 3 | AB34: 0 | AC34: 23 | AD34: 26.25 | AE34: 25 | AF34: 1 | AG34: =COUNTIF(Transfer!E:E,Elem_!B34) -> 0 | AH34: =COUNTIF(Transfer!H:H,Elem_!B34) -> 0 | AI34: =AF34+AG34-AH34 -> 1 | AJ34: 0 | AL34: =ROUND(AK34*$AL$7/$AL$8,0) -> 0 | AN34: =AI34*0.42 -> 0.42 | AQ34: 0 | AR34: =AI34*0.4 -> 0.4 | AV34: =AI34-AU34 -> 1 | AW34: =AI34-AR34 -> 0.6 | AX34: =AV34*0.2 -> 0.2 | BA34: =AV34-AZ34 -> 1 | BD34: =BA34-BC34 -> 1
A35: 119981 | B35: STEC ES | C35: 5 | D35: 30 | E35: 29 | F35: 38 | G35: 35 | H35: 34 | I35: 36 | J35: 33 | K35: 0 | L35: 235 | M35: 30 | N35: 29 | O35: 19 | P35: 18 | Q35: 34 | R35: 36 | S35: 33 | T35: 199 | U35: 1 | V35: 1 | W35: 2 | X35: 2 | Y35: 1 | Z35: 1 | AA35: 1 | AB35: 0 | AC35: 9 | AD35: 10.25 | AE35: 9 | AF35: 1 | AG35: =COUNTIF(Transfer!E:E,Elem_!B35) -> 0 | AH35: =COUNTIF(Transfer!H:H,Elem_!B35) -> 0 | AI35: =AF35+AG35-AH35 -> 1 | AJ35: 0 | AL35: =ROUND(AK35*$AL$7/$AL$8,0) -> 0 | AN35: =AI35*0.42 -> 0.42 | AQ35: 0 | AR35: =AI35*0.4 -> 0.4 | AV35: =AI35-AU35 -> 1 | AW35: =AI35-AR35 -> 0.6 | AX35: =AV35*0.2 -> 0.2 | BA35: =AV35-AZ35 -> 1 | BD35: =BA35-BC35 -> 1
A36: 119955 | B36: Pangan-an ES | C36: 9 | D36: 57 | E36: 54 | F36: 42 | G36: 69 | H36: 60 | I36: 59 | J36: 52 | K36: 0 | L36: 393 | M36: 29 | N36: 27 | O36: 21 | P36: 23 | Q36: 30 | R36: 30 | S36: 26 | T36: 186 | U36: 2 | V36: 2 | W36: 2 | X36: 3 | Y36: 2 | Z36: 2 | AA36: 2 | AB36: 0 | AC36: 15 | AD36: 17.25 | AE36: 16 | AF36: 1 | AG36: =COUNTIF(Transfer!E:E,Elem_!B36) -> 1 | AH36: =COUNTIF(Transfer!H:H,Elem_!B36) -> 0 | AI36: =AF36+AG36-AH36 -> 2 | AJ36: 1 | AK36: 2 | AL36: =ROUND(AK36*$AL$7/$AL$8,0) -> 1 | AN36: =AI36*0.42 -> 0.84 | AP36: transferred out 1 | AQ36: 1 | AR36: =AI36*0.4 -> 0.8 | AT36: 1 | AU36: 1 | AV36: =AI36-AU36 -> 1 | AW36: =AI36-AR36 -> 1.2 | AX36: =AV36*0.2 -> 0.2 | BA36: =AV36-AZ36 -> 1 | BD36: =BA36-BC36 -> 1
A37: 502529 | B37: Caohagan IS | C37: 9 | D37: 15 | E37: 14 | F37: 15 | G37: 26 | H37: 14 | I37: 20 | J37: 13 | K37: 0 | L37: 117 | M37: 15 | N37: 14 | O37: 15 | P37: 26 | Q37: 14 | R37: 20 | S37: 13 | T37: 117 | U37: 1 | V37: 1 | W37: 1 | X37: 1 | Y37: 1 | Z37: 1 | AA37: 1 | AB37: 0 | AC37: 7 | AD37: 8 | AE37: 9 | AF37: -1 | AG37: =COUNTIF(Transfer!E:E,Elem_!B37) -> 0 | AH37: =COUNTIF(Transfer!H:H,Elem_!B37) -> 0 | AI37: =AF37+AG37-AH37 -> -1 | AJ37: 0 | AL37: =ROUND(AK37*$AL$7/$AL$8,0) -> 0 | AN37: =AI37*0.42 -> -0.42 | AQ37: 0 | AR37: =AI37*0.4 -> -0.4 | AV37: =AI37-AU37 -> -1 | AW37: =AI37-AR37 -> -0.6 | AX37: =AV37*0.2 -> -0.2 | BA37: =AV37-AZ37 -> -1 | BD37: =BA37-BC37 -> -1
A38: 119979 | B38: Marigondon ES | C38: 5 | D38: 816 | E38: 777 | F38: 713 | G38: 891 | H38: 862 | I38: 898 | J38: 826 | K38: 181 | L38: 5964 | M38: 54 | N38: 32 | O38: 32 | P38: 33 | Q38: 41 | R38: 43 | S38: 41 | T38: 276 | U38: 15 | V38: 24 | W38: 22 | X38: 27 | Y38: 21 | Z38: 21 | AA38: 20 | AB38: 13 | AC38: 163 | AD38: 185.25 | AE38: 171 | AF38: 14 | AG38: =COUNTIF(Transfer!E:E,Elem_!B38) -> 0 | AH38: =COUNTIF(Transfer!H:H,Elem_!B38) -> 0 | AI38: =AF38+AG38-AH38 -> 14 | AJ38: 11 | AK38: 14 | AL38: =ROUND(AK38*$AL$7/$AL$8,0) -> 6 | AN38: =AI38*0.42 -> 5.88 | AQ38: 6 | AR38: =AI38*0.4 -> 5.6 | AT38: 6 | AU38: 6 | AV38: =AI38-AU38 -> 8 | AW38: =AI38-AR38 -> 8.4 | AX38: =AV38*0.2 -> 1.6 | AY38: 2 | AZ38: 2 | BA38: =AV38-AZ38 -> 6 | BB38: 2 | BC38: 2 | BD38: =BA38-BC38 -> 4
A39: 119965 | B39: Ibo ES | C39: 1 | D39: 138 | E39: 131 | F39: 109 | G39: 135 | H39: 115 | I39: 144 | J39: 109 | K39: 0 | L39: 881 | M39: 46 | N39: 33 | O39: 27 | P39: 27 | Q39: 38 | R39: 36 | S39: 36 | T39: 243 | U39: 3 | V39: 4 | W39: 4 | X39: 5 | Y39: 3 | Z39: 4 | AA39: 3 | AB39: 0 | AC39: 26 | AD39: 29.75 | AE39: 28 | AF39: 2 | AG39: =COUNTIF(Transfer!E:E,Elem_!B39) -> 0 | AH39: =COUNTIF(Transfer!H:H,Elem_!B39) -> 0 | AI39: =AF39+AG39-AH39 -> 2 | AJ39: 1 | AK39: 2 | AL39: =ROUND(AK39*$AL$7/$AL$8,0) -> 1 | AN39: =AI39*0.42 -> 0.84 | AP39: transferred in 1 | AQ39: 1 | AR39: =AI39*0.4 -> 0.8 | AV39: =AI39-AU39 -> 2 | AW39: =AI39-AR39 -> 1.2 | AX39: =AV39*0.2 -> 0.4 | BA39: =AV39-AZ39 -> 2 | BD39: =BA39-BC39 -> 2
A40: 119962 | B40: Tungasan ES | C40: 10 | D40: 53 | E40: 50 | F40: 56 | G40: 60 | H40: 53 | I40: 60 | J40: 61 | K40: 0 | L40: 393 | M40: 53 | N40: 25 | O40: 28 | P40: 30 | Q40: 27 | R40: 30 | S40: 31 | T40: 224 | U40: 1 | V40: 2 | W40: 2 | X40: 2 | Y40: 2 | Z40: 2 | AA40: 2 | AB40: 0 | AC40: 13 | AD40: 15 | AE40: 14 | AF40: 1 | AG40: =COUNTIF(Transfer!E:E,Elem_!B40) -> 1 | AH40: =COUNTIF(Transfer!H:H,Elem_!B40) -> 0 | AI40: =AF40+AG40-AH40 -> 2 | AJ40: 1 | AK40: 2 | AL40: =ROUND(AK40*$AL$7/$AL$8,0) -> 1 | AN40: =AI40*0.42 -> 0.84 | AP40: transferred out 2 | AQ40: 1 | AR40: =AI40*0.4 -> 0.8 | AU40: 1 | AV40: =AI40-AU40 -> 1 | AW40: =AI40-AR40 -> 1.2 | AX40: =AV40*0.2 -> 0.2 | BA40: =AV40-AZ40 -> 1 | BD40: =BA40-BC40 -> 1
A41: 119959 | B41: Suba ES | C41: 9 | D41: 56 | E41: 53 | F41: 29 | G41: 71 | H41: 43 | I41: 38 | J41: 47 | K41: 0 | L41: 337 | M41: 28 | N41: 27 | O41: 29 | P41: 24 | Q41: 43 | R41: 38 | S41: 24 | T41: 213 | U41: 2 | V41: 2 | W41: 1 | X41: 3 | Y41: 1 | Z41: 1 | AA41: 2 | AB41: 0 | AC41: 12 | AD41: 13.75 | AE41: 12 | AF41: 2 | AG41: =COUNTIF(Transfer!E:E,Elem_!B41) -> 0 | AH41: =COUNTIF(Transfer!H:H,Elem_!B41) -> 0 | AI41: =AF41+AG41-AH41 -> 2 | AJ41: 1 | AK41: 2 | AL41: =ROUND(AK41*$AL$7/$AL$8,0) -> 1 | AN41: =AI41*0.42 -> 0.84 | AQ41: 1 | AR41: =AI41*0.4 -> 0.8 | AT41: 1 | AU41: 1 | AV41: =AI41-AU41 -> 1 | AW41: =AI41-AR41 -> 1.2 | AX41: =AV41*0.2 -> 0.2 | BA41: =AV41-AZ41 -> 1 | BB41: 1 | BC41: 1 | BD41: =BA41-BC41 -> 0
A42: 119988 | B42: Kalawisan ES | C42: 8 | D42: 173 | E42: 165 | F42: 175 | G42: 153 | H42: 160 | I42: 161 | J42: 168 | K42: 0 | L42: 1155 | M42: 43 | N42: 33 | O42: 29 | P42: 31 | Q42: 40 | R42: 40 | S42: 42 | T42: 258 | U42: 4 | V42: 5 | W42: 6 | X42: 5 | Y42: 4 | Z42: 4 | AA42: 4 | AB42: 0 | AC42: 32 | AD42: 36.25 | AE42: 33 | AF42: 3 | AG42: =COUNTIF(Transfer!E:E,Elem_!B42) -> 0 | AH42: =COUNTIF(Transfer!H:H,Elem_!B42) -> 2 | AI42: =AF42+AG42-AH42 -> 1 | AJ42: 0 | AL42: =ROUND(AK42*$AL$7/$AL$8,0) -> 0 | AN42: =AI42*0.42 -> 0.42 | AQ42: 0 | AR42: =AI42*0.4 -> 0.4 | AV42: =AI42-AU42 -> 1 | AW42: =AI42-AR42 -> 0.6 | AX42: =AV42*0.2 -> 0.2 | AY42: transfer in | BA42: =AV42-AZ42 -> 1 | BD42: =BA42-BC42 -> 1
A43: 119991 | B43: Poblacion ES | C43: 7 | D43: 85 | E43: 81 | F43: 58 | G43: 72 | H43: 86 | I43: 69 | J43: 77 | K43: 0 | L43: 528 | M43: 43 | N43: 27 | O43: 29 | P43: 24 | Q43: 43 | R43: 35 | S43: 39 | T43: 240 | U43: 2 | V43: 3 | W43: 2 | X43: 3 | Y43: 2 | Z43: 2 | AA43: 2 | AB43: 0 | AC43: 16 | AD43: 18.25 | AE43: 19 | AF43: -1 | AG43: =COUNTIF(Transfer!E:E,Elem_!B43) -> 0 | AH43: =COUNTIF(Transfer!H:H,Elem_!B43) -> 0 | AI43: =AF43+AG43-AH43 -> -1 | AJ43: 0 | AL43: =ROUND(AK43*$AL$7/$AL$8,0) -> 0 | AN43: =AI43*0.42 -> -0.42 | AQ43: 0 | AR43: =AI43*0.4 -> -0.4 | AV43: =AI43-AU43 -> -1 | AW43: =AI43-AR43 -> -0.6 | AX43: =AV43*0.2 -> -0.2 | BA43: =AV43-AZ43 -> -1 | BD43: =BA43-BC43 -> -1
...

Sheet Transfer
B1: TRANSFER ELEM
A2: No. | B2: Name of Applicant | E2: School | F2: Current Position | G2: Home Address | H2: Applied (T In)
B3: Last Name | C3: First Name | D3: MiddleName
A4: 1 | B4: Vergara | C4: Joseph | D4: Romarate | E4: Pangan-an ES | F4: TEACHER III | G4: Commonwealth Brgy. Ibo, LLC | H4: Buaya ES
A5: 2 | B5: Fortuna | C5: Genia | D5: Lozano | E5: Soong ES | F5: TEACHER III | G5: Ticgahon, Bankal LLC | H5: Bankal ES
A6: 3 | B6: Igar | C6: Maria Joy | D6: Aclag | E6: Bankal ES | F6: TEACHER III | G6: Pusok, LL( | H6: Pusok ES
A7: 4 | B7: Alinsub | C7: Fernil | D7: Maglasang | E7: Buyong ES | F7: TEACHER III | G7: BF Country Homes, Pajac LLC | H7: Pajac ES
A8: 5 | B8: Ardines | C8: Jeizel | D8: Tumulak | E8: Buaya ES | F8: TEACHER III | G8: Cordova | H8: Subabasbas ES
A9: 6 | B9: Sarco | C9: Sheila Mae | D9: Masangcay | E9: Tungasan ES | F9: TEACHER I | G9: Lo-oc, LLC | H9: Lapu-Lapu City CES
A10: 7 | B10: Felisilda | C10: Jezel Mae | D10: Tumulak | E10: Buaya ES | F10: TEACHER III | G10: Gun-ob, Kinalumsan | H10: Gun-ob ES
A11: 8 | B11: Marañon | C11: Gester Mae | D11: Benlot | E11: Tingo ES | F11: TEACHER III | G11: Gun-ob, Kinalumsan | H11: Babag II ES
A12: 9 | B12: Aquino | C12: Luida | D12: Ocaba | E12: Lapu-Lapu City CES | F12: TEACHER III | G12: San Miguel, Cordova | H12: Babag II ES
A13: 10 | B13: Francisco | C13: Mercedita | D13: Luna | E13: Buyong ES | F13: TEACHER III | G13: Calawisan, LLC | H13: Kalawisan ES
A14: 11 | B14: Suico | C14: Maria Endie | D14: Alegrado | E14: Maribago ES | F14: TEACHER III | G14: Calawisan, LLC | H14: Kalawisan ES
A15: 12 | B15: Tagsip | C15: Crestelia | D15: Ricafort | E15: Tiangue ES | F15: TEACHER III | G15: TEACHER 1 | H15: Caw-oy ES
